connection to server at "localhost" (127.0.0.1), port 5432 failed: FATAL:  password authentication failed for user "postgres"

Traceback (most recent call last):
  File "/home/thanhtd/database_management/app.py", line 25, in <module>
    connection = psycopg2.connect(**db_params)
  File "/usr/local/lib/python3.10/dist-packages/psycopg2/__init__.py", line 122, in connect
    conn = _connect(dsn, connection_factory=connection_factory, **kwasync)
psycopg2.OperationalError: connection to server at "localhost" (127.0.0.1), port 5432 failed: FATAL:  password authentication failed for user "postgres"




connection to server at "localhost" (127.0.0.1), port 5432 failed: FATAL:  password authentication failed for user "postgres"
connection to server at "localhost" (127.0.0.1), port 5432 failed: FATAL:  password authentication failed for user "postgres"

Traceback (most recent call last):
  File "/home/thanhtd/database_management/app.py", line 24, in <module>
    connection = psycopg2.connect(**db_params)
  File "/usr/local/lib/python3.10/dist-packages/psycopg2/__init__.py", line 122, in connect
    conn = _connect(dsn, connection_factory=connection_factory, **kwasync)
psycopg2.OperationalError: connection to server at "localhost" (127.0.0.1), port 5432 failed: FATAL:  password authentication failed for user "postgres"
connection to server at "localhost" (127.0.0.1), port 5432 failed: FATAL:  password authentication failed for user "postgres"




connection to server at "4.194.192.115", port 5432 failed: FATAL:  password authentication failed for user "postgres"
connection to server at "4.194.192.115", port 5432 failed: FATAL:  password authentication failed for user "postgres"

Traceback (most recent call last):
  File "/home/thanhtd/database_management/app.py", line 24, in <module>
    connection = psycopg2.connect(**db_params)
  File "/usr/local/lib/python3.10/dist-packages/psycopg2/__init__.py", line 122, in connect
    conn = _connect(dsn, connection_factory=connection_factory, **kwasync)
psycopg2.OperationalError: connection to server at "4.194.192.115", port 5432 failed: FATAL:  password authentication failed for user "postgres"
connection to server at "4.194.192.115", port 5432 failed: FATAL:  password authentication failed for user "postgres"




no results to fetch
Traceback (most recent call last):
  File "/home/thanhtd/database_management/app.py", line 24, in <module>
    db_version = cursor.fetchone()
psycopg2.ProgrammingError: no results to fetch



no results to fetch
Traceback (most recent call last):
  File "/home/thanhtd/database_management/app.py", line 24, in <module>
    db_version = cursor.fetchone()
psycopg2.ProgrammingError: no results to fetch



name 'cur' is not defined
Traceback (most recent call last):
  File "/home/thanhtd/database_management/app.py", line 25, in <module>
    cur.execute('SELECT version()')
NameError: name 'cur' is not defined



column "name" does not exist
LINE 1: SELECT "name" FROM user
               ^

Traceback (most recent call last):
  File "/home/thanhtd/database_management/app.py", line 19, in <module>
    selecttest(connection, cursor)
  File "/home/thanhtd/database_management/query.py", line 29, in selecttest
    cursor.execute(search_query)
psycopg2.errors.UndefinedColumn: column "name" does not exist
LINE 1: SELECT "name" FROM user
               ^




selecttest() takes 2 positional arguments but 3 were given
Traceback (most recent call last):
  File "/home/thanhtd/database_management/app.py", line 19, in <module>
    print(selecttest(connection, cursor, 1))
TypeError: selecttest() takes 2 positional arguments but 3 were given



'module' object is not callable
Traceback (most recent call last):
  File "/home/thanhtd/database_management/app.py", line 20, in <module>
    time_booked_pitch = datetime(2023, 11, 1, 20, 30).timestamp()
TypeError: 'module' object is not callable



syntax error at or near "Dinh"
LINE 1: ..._time", "name", "id" FROM "pitch" WHERE "location" = My Dinh
                                                                   ^

Traceback (most recent call last):
  File "/home/thanhtd/database_management/app.py", line 23, in <module>
    print(search_data(connection, cursor, "My Dinh", "test1"))
  File "/home/thanhtd/database_management/query.py", line 18, in search_data
    cursor.execute(search_query)
psycopg2.errors.SyntaxError: syntax error at or near "Dinh"
LINE 1: ..._time", "name", "id" FROM "pitch" WHERE "location" = My Dinh
                                                                   ^




column "My Dinh" does not exist
LINE 1: ...ime", "name", "id" FROM "pitch" WHERE "location" = "My Dinh"
                                                              ^

connection to server at "4.194.192.115", port 5432 failed: keepalives parameter must be an integer

Traceback (most recent call last):
  File "/home/thanhtd/database_management/app.py", line 15, in <module>
    connection = psycopg2.connect(**params)
  File "/home/thanhtd/.local/lib/python3.10/site-packages/psycopg2/__init__.py", line 122, in connect
    conn = _connect(dsn, connection_factory=connection_factory, **kwasync)
psycopg2.OperationalError: connection to server at "4.194.192.115", port 5432 failed: keepalives parameter must be an integer




Composable.__init__() takes 2 positional arguments but 3 were given
Traceback (most recent call last):
  File "/home/thanhtd/database_management/app.py", line 22, in <module>
    selecttest(connection, cursor, id, float(12312312.0))
  File "/home/thanhtd/database_management/query.py", line 34, in selecttest
    select_query_booked = sql.SQL(f"SELECT \"booked_time\" FROM \"pitch\" WHERE \"id\" = {id}").format(sql.Literal(id, begin_time))
TypeError: Composable.__init__() takes 2 positional arguments but 3 were given



Composable.__init__() takes 2 positional arguments but 3 were given
Traceback (most recent call last):
  File "/home/thanhtd/database_management/app.py", line 22, in <module>
    print(selecttest(connection, cursor, 1, float(12312312.0)))
  File "/home/thanhtd/database_management/query.py", line 34, in selecttest
    select_query_booked = sql.SQL(f"SELECT \"booked_time\" FROM \"pitch\" WHERE \"id\" = {id}").format(sql.Literal(id, begin_time))
TypeError: Composable.__init__() takes 2 positional arguments but 3 were given



name 'transaction' is not defined
Traceback (most recent call last):
  File "/home/thanhtd/database_management/app.py", line 23, in <module>
    transaction.rollback()
NameError: name 'transaction' is not defined



syntax error at or near "Tòng"
LINE 1: ... name, email, phone, created_at) VALUES (6123, Võ Tòng, voto...
                                                             ^

Traceback (most recent call last):
  File "/home/thanhtd/database_management/query.py", line 115, in create_user
    cursor.execute(sql_create_user)
psycopg2.errors.SyntaxError: syntax error at or near "Tòng"
LINE 1: ... name, email, phone, created_at) VALUES (6123, Võ Tòng, voto...
                                                             ^




syntax error at or near "09"
LINE 1: ...votongdanhho@gmail.com', '0987654321', 2023-10-30 09:54:39.3...
                                                             ^

Traceback (most recent call last):
  File "/home/thanhtd/database_management/query.py", line 115, in create_user
    cursor.execute(sql_create_user)
psycopg2.errors.SyntaxError: syntax error at or near "09"
LINE 1: ...votongdanhho@gmail.com', '0987654321', 2023-10-30 09:54:39.3...
                                                             ^




null value in column "deleted" of relation "user" violates not-null constraint
DETAIL:  Failing row contains (1, 6123, Võ Tòng, votongdanhho@gmail.com, 0987654321, 2023-10-30 09:56:20.493939, null, null).

Traceback (most recent call last):
  File "/home/thanhtd/database_management/query.py", line 115, in create_user
    cursor.execute(sql_create_user)
psycopg2.errors.NotNullViolation: null value in column "deleted" of relation "user" violates not-null constraint
DETAIL:  Failing row contains (1, 6123, Võ Tòng, votongdanhho@gmail.com, 0987654321, 2023-10-30 09:56:20.493939, null, null).




null value in column "deleted" of relation "user" violates not-null constraint
DETAIL:  Failing row contains (2, 6123, Võ Tòng, votongdanhho@gmail.com, 0987654321, 2023-10-30 09:57:52.556477, null, null).

Traceback (most recent call last):
  File "/home/thanhtd/database_management/query.py", line 115, in create_user
    cursor.execute(sql_create_user)
psycopg2.errors.NotNullViolation: null value in column "deleted" of relation "user" violates not-null constraint
DETAIL:  Failing row contains (2, 6123, Võ Tòng, votongdanhho@gmail.com, 0987654321, 2023-10-30 09:57:52.556477, null, null).




date/time field value out of range: "0987654321"
LINE 1: ...booked_time, pending, created_at) VALUES (1, '2', '098765432...
                                                             ^
HINT:  Perhaps you need a different "datestyle" setting.

Traceback (most recent call last):
  File "/home/thanhtd/database_management/query.py", line 97, in create_pending_match
    cursor.execute(sql_query)
psycopg2.errors.DatetimeFieldOverflow: date/time field value out of range: "0987654321"
LINE 1: ...booked_time, pending, created_at) VALUES (1, '2', '098765432...
                                                             ^
HINT:  Perhaps you need a different "datestyle" setting.


duplicate key value violates unique constraint "psid_unique"
DETAIL:  Key (psid)=(6) already exists.

Traceback (most recent call last):
  File "/home/thanhtd/database_management/query.py", line 130, in create_user
    cursor.execute(sql_create_user)
psycopg2.errors.UniqueViolation: duplicate key value violates unique constraint "psid_unique"
DETAIL:  Key (psid)=(6) already exists.




duplicate key value violates unique constraint "psid_unique"
DETAIL:  Key (psid)=(6) already exists.

Traceback (most recent call last):
  File "/home/thanhtd/database_management/query.py", line 130, in create_user
    cursor.execute(sql_create_user)
psycopg2.errors.UniqueViolation: duplicate key value violates unique constraint "psid_unique"
DETAIL:  Key (psid)=(6) already exists.




column "id" does not exist
LINE 1: SELECT id FROM USER WHERE psid = 6123
               ^

Traceback (most recent call last):
  File "/home/thanhtd/database_management/query.py", line 90, in create_pending_match
    cursor.execute(get_user_id)
psycopg2.errors.UndefinedColumn: column "id" does not exist
LINE 1: SELECT id FROM USER WHERE psid = 6123
               ^




relation "USER" does not exist
LINE 1: SELECT id FROM "USER" WHERE psid = 6123
                       ^

Traceback (most recent call last):
  File "/home/thanhtd/database_management/query.py", line 90, in create_pending_match
    cursor.execute(get_user_id)
psycopg2.errors.UndefinedTable: relation "USER" does not exist
LINE 1: SELECT id FROM "USER" WHERE psid = 6123
                       ^




relation "USER" does not exist
LINE 1: SELECT id FROM "USER" WHERE psid = '6123'
                       ^

Traceback (most recent call last):
  File "/home/thanhtd/database_management/query.py", line 90, in create_pending_match
    cursor.execute(get_user_id)
psycopg2.errors.UndefinedTable: relation "USER" does not exist
LINE 1: SELECT id FROM "USER" WHERE psid = '6123'
                       ^




'psycopg2.extensions.connection' object has no attribute 'fetchall'
Traceback (most recent call last):
  File "/home/thanhtd/database_management/query.py", line 91, in create_pending_match
    user_id = int(connection.fetchall())
AttributeError: 'psycopg2.extensions.connection' object has no attribute 'fetchall'



int() argument must be a string, a bytes-like object or a real number, not 'list'
Traceback (most recent call last):
  File "/home/thanhtd/database_management/query.py", line 91, in create_pending_match
    user_id = int(cursor.fetchall())
TypeError: int() argument must be a string, a bytes-like object or a real number, not 'list'



syntax error at or near ")"
LINE 1: ...d, interval_time, pending, created_at) VALUES ((3,), 4, '{"s...
                                                             ^

Traceback (most recent call last):
  File "/home/thanhtd/database_management/query.py", line 105, in create_pending_match
    cursor.execute(sql_query)
psycopg2.errors.SyntaxError: syntax error at or near ")"
LINE 1: ...d, interval_time, pending, created_at) VALUES ((3,), 4, '{"s...
                                                             ^




int() argument must be a string, a bytes-like object or a real number, not 'tuple'
Traceback (most recent call last):
  File "/home/thanhtd/database_management/query.py", line 91, in create_pending_match
    user_id = int(cursor.fetchall()[0])
TypeError: int() argument must be a string, a bytes-like object or a real number, not 'tuple'



list indices must be integers or slices, not str
Traceback (most recent call last):
  File "/home/thanhtd/database_management/query.py", line 110, in create_pending_match
    print(vacant_shift_dict['start_time'])
TypeError: list indices must be integers or slices, not str



list indices must be integers or slices, not str
Traceback (most recent call last):
  File "/home/thanhtd/database_management/query.py", line 110, in create_pending_match
    print(vacant_shift_dict['start_time'])
TypeError: list indices must be integers or slices, not str



list indices must be integers or slices, not str
Traceback (most recent call last):
  File "/home/thanhtd/database_management/query.py", line 110, in create_pending_match
    print(vacant_shift_dict['start_time'])
TypeError: list indices must be integers or slices, not str



list indices must be integers or slices, not str
Traceback (most recent call last):
  File "/home/thanhtd/database_management/query.py", line 110, in create_pending_match
    print(vacant_shift_dict['start_time'])
TypeError: list indices must be integers or slices, not str



list indices must be integers or slices, not str
Traceback (most recent call last):
  File "/home/thanhtd/database_management/query.py", line 112, in create_pending_match
    print(vacant_shift_dict['start_time'])
TypeError: list indices must be integers or slices, not str



list indices must be integers or slices, not str
Traceback (most recent call last):
  File "/home/thanhtd/database_management/query.py", line 114, in create_pending_match
    print(vacant_shift_dict['start_time'])
TypeError: list indices must be integers or slices, not str



object of type 'bool' has no len()
Traceback (most recent call last):
  File "/home/thanhtd/database_management/query.py", line 109, in create_pending_match
    vacant_shift_dict = convertJsonToDict(full_interval_pitch, begin_interval, end_interval)
  File "/home/thanhtd/database_management/query.py", line 227, in convertJsonToDict
    time_stamps = findVacantTime(list, begin_time, end_time)
  File "/home/thanhtd/database_management/query.py", line 269, in findVacantTime
    if len(shift_available == 0):
TypeError: object of type 'bool' has no len()



object of type 'bool' has no len()
Traceback (most recent call last):
  File "/home/thanhtd/database_management/query.py", line 109, in create_pending_match
    vacant_shift_dict = convertJsonToDict(full_interval_pitch, begin_interval, end_interval)
  File "/home/thanhtd/database_management/query.py", line 227, in convertJsonToDict
    time_stamps = findVacantTime(list, begin_time, end_time)
  File "/home/thanhtd/database_management/query.py", line 269, in findVacantTime
    if len(shift_available == 0):
TypeError: object of type 'bool' has no len()



0
Traceback (most recent call last):
  File "/home/thanhtd/database_management/query.py", line 110, in create_pending_match
    if len(vacant_shift_dict) == 1 and vacant_shift_dict[0][0] == begin_interval and vacant_shift_dict[0][1] == end_interval:
KeyError: 0



0
Traceback (most recent call last):
  File "/home/thanhtd/database_management/query.py", line 112, in create_pending_match
    if len(vacant_shift_dict) == 1 and vacant_shift_dict[0][0] == begin_interval and vacant_shift_dict[0][1] == end_interval:
KeyError: 0



list index out of range
Traceback (most recent call last):
  File "/home/thanhtd/database_management/query.py", line 107, in create_pending_match
    vacant_shift_dict = convertJsonToDict(full_interval_pitch, begin_interval, end_interval)
  File "/home/thanhtd/database_management/query.py", line 217, in convertJsonToDict
    list = [(pitchs_booked_time[0]['start_time'], pitchs_booked_time[0]['end_time'])]
IndexError: list index out of range



list index out of range
Traceback (most recent call last):
  File "/home/thanhtd/database_management/query.py", line 107, in create_pending_match
    vacant_shift_dict = convertJsonToDict(full_interval_pitch, begin_interval, end_interval)
  File "/home/thanhtd/database_management/query.py", line 217, in convertJsonToDict
    list = [(pitchs_booked_time[0]['start_time'], pitchs_booked_time[0]['end_time'])]
IndexError: list index out of range



list index out of range
Traceback (most recent call last):
  File "/home/thanhtd/database_management/query.py", line 107, in create_pending_match
    vacant_shift_dict = convertJsonToDict(full_interval_pitch, begin_interval, end_interval)
  File "/home/thanhtd/database_management/query.py", line 218, in convertJsonToDict
    list = [(pitchs_booked_time[0]['start_time'], pitchs_booked_time[0]['end_time'])]
IndexError: list index out of range



list index out of range
Traceback (most recent call last):
  File "/home/thanhtd/database_management/query.py", line 108, in create_pending_match
    vacant_shift_dict = convertJsonToDict(full_interval_pitch, begin_interval, end_interval)
  File "/home/thanhtd/database_management/query.py", line 219, in convertJsonToDict
    list = [(pitchs_booked_time[0]['start_time'], pitchs_booked_time[0]['end_time'])]
IndexError: list index out of range



